
entity projkect kylegoyette launch-arti-demo
[34m[1mwandb[39m[22m: [32m[41mERROR[39m[49m Error while calling W&B API: failed to find run launch-arti-demo/i49x1iex (<Response [404]>)
[34m[1mwandb[39m[22m: [32m[41mERROR[39m[49m Permission denied to access kylegoyette/launch-arti-demo-tests/i49x1iex
Traceback (most recent call last):
  File "/Users/kyle/newcli/client/wandb/sdk/lib/retry.py", line 102, in __call__
    result = self._call_fn(*args, **kwargs)
  File "/Users/kyle/newcli/client/wandb/sdk/internal/internal_api.py", line 136, in execute
    six.reraise(*sys.exc_info())
  File "/Users/kyle/.pyenv/versions/3.6.8/Python.framework/Versions/3.6/lib/python3.6/site-packages/six.py", line 719, in reraise
    raise value
  File "/Users/kyle/newcli/client/wandb/sdk/internal/internal_api.py", line 130, in execute
    return self.client.execute(*args, **kwargs)
  File "/Users/kyle/newcli/client/wandb/vendor/gql-0.2.0/gql/client.py", line 52, in execute
    result = self._get_result(document, *args, **kwargs)
  File "/Users/kyle/newcli/client/wandb/vendor/gql-0.2.0/gql/client.py", line 60, in _get_result
    return self.transport.execute(document, *args, **kwargs)
  File "/Users/kyle/newcli/client/wandb/vendor/gql-0.2.0/gql/transport/requests.py", line 39, in execute
    request.raise_for_status()
  File "/Users/kyle/.pyenv/versions/3.6.8/Python.framework/Versions/3.6/lib/python3.6/site-packages/requests/models.py", line 943, in raise_for_status
    raise HTTPError(http_error_msg, response=self)
requests.exceptions.HTTPError: 404 Client Error: Not Found for url: https://api.wandb.ai/graphql
During handling of the above exception, another exception occurred:
Traceback (most recent call last):
  File "main.py", line 29, in <module>
    dataset = run.use_artifact('launch-arti-demo/my-orig-dataset:latest')
  File "/Users/kyle/newcli/client/wandb/sdk/wandb_run.py", line 2111, in use_artifact
    artifact.id, entity_name=artifact.entity, project_name=artifact.project
  File "/Users/kyle/newcli/client/wandb/apis/internal.py", line 123, in use_artifact
    return self.api.use_artifact(*args, **kwargs)
  File "/Users/kyle/newcli/client/wandb/sdk/internal/internal_api.py", line 1838, in use_artifact
    "artifactID": artifact_id,
  File "/Users/kyle/newcli/client/wandb/sdk/lib/retry.py", line 118, in __call__
    if not check_retry_fn(e):
  File "/Users/kyle/newcli/client/wandb/util.py", line 807, in no_retry_auth
    raise CommError("Permission denied to access {}".format(wandb.run.path))
wandb.errors.CommError: Permission denied to access kylegoyette/launch-arti-demo-tests/i49x1iex